Workbook

Sheet Permits by Type
B1: Permits by Water Type | D1: Permits by County and Water Type | G1: Permits by Use Purpose | I1: Provisional-Temporary Permits
B3: Long-Term Water Rights in Oklahoma
B6: PERMITS BY WATER TYPE | D6: 45903
B8: Type | C8: Number | D8: Amount (AFY)
B9: Groundwater | C9: =[1]WR_sum_P_by_WaterCode!B2 -> 11575 | D9: =[1]WR_sum_P_by_WaterCode!C2 -> 4212486.6
B10: Surface Water | C10: =[1]WR_sum_P_by_WaterCode!B3 -> 2185 | D10: =[1]WR_sum_P_by_WaterCode!C3 -> 2851269
B11: TOTAL | C11: =SUM(C9:C10) -> 13760 | D11: =SUM(D9:D10) -> 7063755.6
B14: PERMITS BY TYPE
B16: Groundwater
B17: Type of Permit | C17: Number | D17: Amount (AFY)
B18: =[2]WR_sum_P_by_Type!A3 -> Prior Right | C18: =[2]WR_sum_P_by_Type!C3 -> 5199 | D18: =[2]WR_sum_P_by_Type!D3 -> 1237658.9
B19: =[2]WR_sum_P_by_Type!A4 -> Regular | C19: =[2]WR_sum_P_by_Type!C4 -> 2941 | D19: =[2]WR_sum_P_by_Type!D4 -> 1566667.4
B20: =[2]WR_sum_P_by_Type!A7 -> Temporary | C20: =[2]WR_sum_P_by_Type!C7 -> 3435 | D20: =[2]WR_sum_P_by_Type!D7 -> 1408160.3
B21: Special | C21: 0 | D21: 0
B22: TOTAL | C22: =SUM(C18:C21) -> 11575 | D22: =SUM(D18:D21) -> 4212486.6
B24: Surface Water
B25: Type of Permit | C25: Number | D25: Amount (AFY)
B26: =[2]WR_sum_P_by_Type!A5 -> Regular | C26: =[2]WR_sum_P_by_Type!C5 -> 1694 | D26: =[2]WR_sum_P_by_Type!D5 -> 2079360.6
B27: =[2]WR_sum_P_by_Type!A6 -> Seasonal | C27: =[2]WR_sum_P_by_Type!C6 -> 14 | D27: =[2]WR_sum_P_by_Type!D6 -> 10243
B28: =[2]WR_sum_P_by_Type!A9 -> Vested | C28: =[2]WR_sum_P_by_Type!C9 -> 418 | D28: =[2]WR_sum_P_by_Type!D9 -> 513908.1
B29: =[2]WR_sum_P_by_Type!A8 -> Term | C29: =[2]WR_sum_P_by_Type!C8 -> 48 | D29: =[2]WR_sum_P_by_Type!D8 -> 29919.3
B30: =[2]WR_sum_P_by_Type!A2 -> (GRDA) | C30: =[2]WR_sum_P_by_Type!C2 -> 11 | D30: =[2]WR_sum_P_by_Type!D2 -> 217838
B31: TOTAL | C31: =SUM(C26:C30) -> 2185 | D31: =SUM(D26:D30) -> 2851269
B33: The data shown on this page is a summary of water rights information extracted from the OWRB's database.

Sheet Permits by County and Type
B1: Permits by Water Type | D1: Permits by County and Water Type | G1: Permits by Use Purpose | J1: Provisional-Temporary Permits
B3: Long-Term Water Rights by County
B6: PERMITS BY COUNTY AND WATER TYPE | G6: 45903
C8: G - Groundwater
C9: S - Surface Water
B11: County | C11: Type | D11: Number | E11: Amount Permitted (AFY) | F11: Total County (#) | G11: Total County (AFY)
B12: =[3]WR_sum_P_by_County_GWSW!A2 -> Adair | C12: =[3]WR_sum_P_by_County_GWSW!B2 -> G | D12: =[3]WR_sum_P_by_County_GWSW!C2 -> 38 | E12: =[3]WR_sum_P_by_County_GWSW!D2 -> 2048.5
C13: =[3]WR_sum_P_by_County_GWSW!B3 -> S | D13: =[3]WR_sum_P_by_County_GWSW!C3 -> 37 | E13: =[3]WR_sum_P_by_County_GWSW!D3 -> 13716.6 | F13: =SUM(D12:D13) -> 75 | G13: =SUM(E12:E13) -> 15765.1
B15: =[3]WR_sum_P_by_County_GWSW!A4 -> Alfalfa | C15: =[3]WR_sum_P_by_County_GWSW!B4 -> G | D15: =[3]WR_sum_P_by_County_GWSW!C4 -> 109 | E15: =[3]WR_sum_P_by_County_GWSW!D4 -> 27070.7
C16: =[3]WR_sum_P_by_County_GWSW!B5 -> S | D16: =[3]WR_sum_P_by_County_GWSW!C5 -> 6 | E16: =[3]WR_sum_P_by_County_GWSW!D5 -> 4276 | F16: =SUM(D15:D16) -> 115 | G16: =SUM(E15:E16) -> 31346.7
B18: =[3]WR_sum_P_by_County_GWSW!A6 -> Atoka | C18: =[3]WR_sum_P_by_County_GWSW!B6 -> G | D18: =[3]WR_sum_P_by_County_GWSW!C6 -> 14 | E18: =[3]WR_sum_P_by_County_GWSW!D6 -> 8460.9
C19: =[3]WR_sum_P_by_County_GWSW!B7 -> S | D19: =[3]WR_sum_P_by_County_GWSW!C7 -> 32 | E19: =[3]WR_sum_P_by_County_GWSW!D7 -> 165067.2 | F19: =SUM(D18:D19) -> 46 | G19: =SUM(E18:E19) -> 173528.1
B21: =[3]WR_sum_P_by_County_GWSW!A8 -> Beaver | C21: =[3]WR_sum_P_by_County_GWSW!B8 -> G | D21: =[3]WR_sum_P_by_County_GWSW!C8 -> 519 | E21: =[3]WR_sum_P_by_County_GWSW!D8 -> 345898
C22: =[3]WR_sum_P_by_County_GWSW!B9 -> S | D22: =[3]WR_sum_P_by_County_GWSW!C9 -> 6 | E22: =[3]WR_sum_P_by_County_GWSW!D9 -> 721 | F22: =SUM(D21:D22) -> 525 | G22: =SUM(E21:E22) -> 346619
B24: =[3]WR_sum_P_by_County_GWSW!A10 -> Beckham | C24: =[3]WR_sum_P_by_County_GWSW!B10 -> G | D24: =[3]WR_sum_P_by_County_GWSW!C10 -> 274 | E24: =[3]WR_sum_P_by_County_GWSW!D10 -> 79302.3
C25: =[3]WR_sum_P_by_County_GWSW!B11 -> S | D25: =[3]WR_sum_P_by_County_GWSW!C11 -> 17 | E25: =[3]WR_sum_P_by_County_GWSW!D11 -> 2368 | F25: =SUM(D24:D25) -> 291 | G25: =SUM(E24:E25) -> 81670.3
B27: =[3]WR_sum_P_by_County_GWSW!A12 -> Blaine | C27: =[3]WR_sum_P_by_County_GWSW!B12 -> G | D27: =[3]WR_sum_P_by_County_GWSW!C12 -> 161 | E27: =[3]WR_sum_P_by_County_GWSW!D12 -> 47795.3
C28: =[3]WR_sum_P_by_County_GWSW!B13 -> S | D28: =[3]WR_sum_P_by_County_GWSW!C13 -> 35 | E28: =[3]WR_sum_P_by_County_GWSW!D13 -> 10293.1 | F28: =SUM(D27:D28) -> 196 | G28: =SUM(E27:E28) -> 58088.4
B30: =[3]WR_sum_P_by_County_GWSW!A14 -> Bryan | C30: =[3]WR_sum_P_by_County_GWSW!B14 -> G | D30: =[3]WR_sum_P_by_County_GWSW!C14 -> 60 | E30: =[3]WR_sum_P_by_County_GWSW!D14 -> 25575.3
C31: =[3]WR_sum_P_by_County_GWSW!B15 -> S | D31: =[3]WR_sum_P_by_County_GWSW!C15 -> 81 | E31: =[3]WR_sum_P_by_County_GWSW!D15 -> 48808.2 | F31: =SUM(D30:D31) -> 141 | G31: =SUM(E30:E31) -> 74383.5
B33: =[3]WR_sum_P_by_County_GWSW!A16 -> Caddo | C33: =[3]WR_sum_P_by_County_GWSW!B16 -> G | D33: =[3]WR_sum_P_by_County_GWSW!C16 -> 1258 | E33: =[3]WR_sum_P_by_County_GWSW!D16 -> 233244.5
C34: =[3]WR_sum_P_by_County_GWSW!B17 -> S | D34: =[3]WR_sum_P_by_County_GWSW!C17 -> 84 | E34: =[3]WR_sum_P_by_County_GWSW!D17 -> 36672.9 | F34: =SUM(D33:D34) -> 1342 | G34: =SUM(E33:E34) -> 269917.4
B36: =[3]WR_sum_P_by_County_GWSW!A18 -> Canadian | C36: =[3]WR_sum_P_by_County_GWSW!B18 -> G | D36: =[3]WR_sum_P_by_County_GWSW!C18 -> 367 | E36: =[3]WR_sum_P_by_County_GWSW!D18 -> 97544.6
C37: =[3]WR_sum_P_by_County_GWSW!B19 -> S | D37: =[3]WR_sum_P_by_County_GWSW!C19 -> 38 | E37: =[3]WR_sum_P_by_County_GWSW!D19 -> 14464.2 | F37: =SUM(D36:D37) -> 405 | G37: =SUM(E36:E37) -> 112008.8
B39: =[3]WR_sum_P_by_County_GWSW!A20 -> Carter | C39: =[3]WR_sum_P_by_County_GWSW!B20 -> G | D39: =[3]WR_sum_P_by_County_GWSW!C20 -> 54 | E39: =[3]WR_sum_P_by_County_GWSW!D20 -> 23765.9
C40: =[3]WR_sum_P_by_County_GWSW!B21 -> S | D40: =[3]WR_sum_P_by_County_GWSW!C21 -> 30 | E40: =[3]WR_sum_P_by_County_GWSW!D21 -> 25568 | F40: =SUM(D39:D40) -> 84 | G40: =SUM(E39:E40) -> 49333.9
B42: =[3]WR_sum_P_by_County_GWSW!A22 -> Cherokee | C42: =[3]WR_sum_P_by_County_GWSW!B22 -> G | D42: =[3]WR_sum_P_by_County_GWSW!C22 -> 27 | E42: =[3]WR_sum_P_by_County_GWSW!D22 -> 1636
C43: =[3]WR_sum_P_by_County_GWSW!B23 -> S | D43: =[3]WR_sum_P_by_County_GWSW!C23 -> 48 | E43: =[3]WR_sum_P_by_County_GWSW!D23 -> 38456.9 | F43: =SUM(D42:D43) -> 75 | G43: =SUM(E42:E43) -> 40092.9
B45: =[3]WR_sum_P_by_County_GWSW!A24 -> Choctaw | C45: =[3]WR_sum_P_by_County_GWSW!B24 -> G | D45: =[3]WR_sum_P_by_County_GWSW!C24 -> 28 | E45: =[3]WR_sum_P_by_County_GWSW!D24 -> 15890.4
C46: =[3]WR_sum_P_by_County_GWSW!B25 -> S | D46: =[3]WR_sum_P_by_County_GWSW!C25 -> 32 | E46: =[3]WR_sum_P_by_County_GWSW!D25 -> 65128 | F46: =SUM(D45:D46) -> 60 | G46: =SUM(E45:E46) -> 81018.4
B48: =[3]WR_sum_P_by_County_GWSW!A26 -> Cimarron | C48: =[3]WR_sum_P_by_County_GWSW!B26 -> G | D48: =[3]WR_sum_P_by_County_GWSW!C26 -> 551 | E48: =[3]WR_sum_P_by_County_GWSW!D26 -> 350021
C49: =[3]WR_sum_P_by_County_GWSW!B27 -> S | D49: =[3]WR_sum_P_by_County_GWSW!C27 -> 8 | E49: =[3]WR_sum_P_by_County_GWSW!D27 -> 4128 | F49: =SUM(D48:D49) -> 559 | G49: =SUM(E48:E49) -> 354149
B51: =[3]WR_sum_P_by_County_GWSW!A28 -> Cleveland | C51: =[3]WR_sum_P_by_County_GWSW!B28 -> G | D51: =[3]WR_sum_P_by_County_GWSW!C28 -> 137 | E51: =[3]WR_sum_P_by_County_GWSW!D28 -> 100934.1
C52: =[3]WR_sum_P_by_County_GWSW!B29 -> S | D52: =[3]WR_sum_P_by_County_GWSW!C29 -> 13 | E52: =[3]WR_sum_P_by_County_GWSW!D29 -> 37012 | F52: =SUM(D51:D52) -> 150 | G52: =SUM(E51:E52) -> 137946.1
B54: =[3]WR_sum_P_by_County_GWSW!A30 -> Coal | C54: =[3]WR_sum_P_by_County_GWSW!B30 -> G | D54: =[3]WR_sum_P_by_County_GWSW!C30 -> 8 | E54: =[3]WR_sum_P_by_County_GWSW!D30 -> 819
C55: =[3]WR_sum_P_by_County_GWSW!B31 -> S | D55: =[3]WR_sum_P_by_County_GWSW!C31 -> 19 | E55: =[3]WR_sum_P_by_County_GWSW!D31 -> 7719.6 | F55: =SUM(D54:D55) -> 27 | G55: =SUM(E54:E55) -> 8538.6
B57: =[3]WR_sum_P_by_County_GWSW!A32 -> Comanche | C57: =[3]WR_sum_P_by_County_GWSW!B32 -> G | D57: =[3]WR_sum_P_by_County_GWSW!C32 -> 78 | E57: =[3]WR_sum_P_by_County_GWSW!D32 -> 20772
C58: =[3]WR_sum_P_by_County_GWSW!B33 -> S | D58: =[3]WR_sum_P_by_County_GWSW!C33 -> 38 | E58: =[3]WR_sum_P_by_County_GWSW!D33 -> 51484.9 | F58: =SUM(D57:D58) -> 116 | G58: =SUM(E57:E58) -> 72256.9
B60: =[3]WR_sum_P_by_County_GWSW!A34 -> Cotton | C60: =[3]WR_sum_P_by_County_GWSW!B34 -> G | D60: =[3]WR_sum_P_by_County_GWSW!C34 -> 30 | E60: =[3]WR_sum_P_by_County_GWSW!D34 -> 6180
C61: =[3]WR_sum_P_by_County_GWSW!B35 -> S | D61: =[3]WR_sum_P_by_County_GWSW!C35 -> 10 | E61: =[3]WR_sum_P_by_County_GWSW!D35 -> 1391 | F61: =SUM(D60:D61) -> 40 | G61: =SUM(E60:E61) -> 7571
...

Sheet Permits by Use Purpose
B1: Permits by Water Type | D1: Permits by County and Water Type | G1: Permits by Use Purpose | J1: Provisional-Temporary Permits
B3: Long-Term Water Rights by Purpose
B5: PERMITS BY USE PURPOSE | E5: 45903
C7: G - Groundwater
C8: S - Surface Water
B10: Use Purpose | C10: Type | D10: Amount (AFY) | E10: Total Amount (AFY)
B11: =[4]WR_sum_P_by_Purpose_GWSW!A2 -> Agriculture | C11: =[4]WR_sum_P_by_Purpose_GWSW!B2 -> G | D11: =[4]WR_sum_P_by_Purpose_GWSW!D2 -> 97696.9
C12: =[4]WR_sum_P_by_Purpose_GWSW!B3 -> S | D12: =[4]WR_sum_P_by_Purpose_GWSW!D3 -> 7025.7 | E12: =SUM(D11:D12) -> 104722.6
B14: =[4]WR_sum_P_by_Purpose_GWSW!A4 -> Commercial | C14: =[4]WR_sum_P_by_Purpose_GWSW!B4 -> G | D14: =[4]WR_sum_P_by_Purpose_GWSW!D4 -> 20476.9
C15: =[4]WR_sum_P_by_Purpose_GWSW!B5 -> S | D15: =[4]WR_sum_P_by_Purpose_GWSW!D5 -> 492.5 | E15: =SUM(D14:D15) -> 20969.4
B17: =[4]WR_sum_P_by_Purpose_GWSW!A6 -> Industrial | C17: =[4]WR_sum_P_by_Purpose_GWSW!B6 -> G | D17: =[4]WR_sum_P_by_Purpose_GWSW!D6 -> 80398.9
C18: =[4]WR_sum_P_by_Purpose_GWSW!B7 -> S | D18: =[4]WR_sum_P_by_Purpose_GWSW!D7 -> 103970.7 | E18: =SUM(D17:D18) -> 184369.6
B20: =[4]WR_sum_P_by_Purpose_GWSW!A8 -> Irrigation | C20: =[4]WR_sum_P_by_Purpose_GWSW!B8 -> G | D20: =[4]WR_sum_P_by_Purpose_GWSW!D8 -> 3131547.8
C21: =[4]WR_sum_P_by_Purpose_GWSW!B9 -> S | D21: =[4]WR_sum_P_by_Purpose_GWSW!D9 -> 407891.8 | E21: =SUM(D20:D21) -> 3539439.6
B23: =[4]WR_sum_P_by_Purpose_GWSW!A10 -> Oil, Gas & Mining | C23: =[4]WR_sum_P_by_Purpose_GWSW!B10 -> G | D23: =[4]WR_sum_P_by_Purpose_GWSW!D10 -> 157974.4
C24: =[4]WR_sum_P_by_Purpose_GWSW!B11 -> S | D24: =[4]WR_sum_P_by_Purpose_GWSW!D11 -> 158523.8 | E24: =SUM(D23:D24) -> 316498.2
B26: =[4]WR_sum_P_by_Purpose_GWSW!A14 -> Power | C26: =[4]WR_sum_P_by_Purpose_GWSW!B14 -> G | D26: =[4]WR_sum_P_by_Purpose_GWSW!D14 -> 31964.5
C27: =[4]WR_sum_P_by_Purpose_GWSW!B15 -> S | D27: =[4]WR_sum_P_by_Purpose_GWSW!D15 -> 364049 | E27: =SUM(D26:D27) -> 396013.5
B29: =[4]WR_sum_P_by_Purpose_GWSW!A16 -> Public Water Supply | C29: =[4]WR_sum_P_by_Purpose_GWSW!B16 -> G | D29: =[4]WR_sum_P_by_Purpose_GWSW!D16 -> 673149.4
C30: =[4]WR_sum_P_by_Purpose_GWSW!B17 -> S | D30: =[4]WR_sum_P_by_Purpose_GWSW!D17 -> 1656759.4 | E30: =SUM(D29:D30) -> 2329908.8
B32: =[4]WR_sum_P_by_Purpose_GWSW!A18 -> Recreation, Fish & Wildlife | C32: =[4]WR_sum_P_by_Purpose_GWSW!B18 -> G | D32: =[4]WR_sum_P_by_Purpose_GWSW!D18 -> 17131.7
C33: =[4]WR_sum_P_by_Purpose_GWSW!B19 -> S | D33: =[4]WR_sum_P_by_Purpose_GWSW!D19 -> 150556.1 | E33: =SUM(D32:D33) -> 167687.8
B35: =[4]WR_sum_P_by_Purpose_GWSW!A12 -> Other | C35: =[4]WR_sum_P_by_Purpose_GWSW!B12 -> G | D35: =[4]WR_sum_P_by_Purpose_GWSW!D12 -> 1362.6
C36: =[4]WR_sum_P_by_Purpose_GWSW!B13 -> S | D36: =[4]WR_sum_P_by_Purpose_GWSW!D13 -> 2000 | E36: =SUM(D35:D36) -> 3362.6
B68: The data shown on this page is a summary of water rights information extracted from the OWRB's database.

Sheet Provisional-Temporary Permits
B1: Permits by Water Type | D1: Permits by County and Water Type | F1: Permits by Use Purpose | I1: Provisional-Temporary Permits
B3: 90-Day Provisional-Temporary Permits
B6: Total Number and Permitted Amount of PTs by Year
B8: Year | C8: Number of Permits | D8: Total Amount Permitted (Acre-Feet) | L8: Maps
B9: =[5]WR_sum_PT_Year_AF!A10 -> 2005 | C9: =[5]WR_sum_PT_Year_AF!B10 -> 1686 | D9: =[5]WR_sum_PT_Year_AF!C10 -> 15524.3 | J9: (Active) 90-Day Provisional Temporary Permits
B10: =[5]WR_sum_PT_Year_AF!A11 -> 2006 | C10: =[5]WR_sum_PT_Year_AF!B11 -> 1879 | D10: =[5]WR_sum_PT_Year_AF!C11 -> 14213.3 | J10: (2025) 90-Day Provisional Temporary Permits
B11: =[5]WR_sum_PT_Year_AF!A12 -> 2007 | C11: =[5]WR_sum_PT_Year_AF!B12 -> 1836 | D11: =[5]WR_sum_PT_Year_AF!C12 -> 8709.2 | J11: (Historical) 90-Day Provisional Temporary Permits
B12: =[5]WR_sum_PT_Year_AF!A13 -> 2008 | C12: =[5]WR_sum_PT_Year_AF!B13 -> 2044 | D12: =[5]WR_sum_PT_Year_AF!C13 -> 18773
B13: =[5]WR_sum_PT_Year_AF!A14 -> 2009 | C13: =[5]WR_sum_PT_Year_AF!B14 -> 945 | D13: =[5]WR_sum_PT_Year_AF!C14 -> 14859.3
B14: =[5]WR_sum_PT_Year_AF!A15 -> 2010 | C14: =[5]WR_sum_PT_Year_AF!B15 -> 1349 | D14: =[5]WR_sum_PT_Year_AF!C15 -> 17293.5
B15: =[5]WR_sum_PT_Year_AF!A16 -> 2011 | C15: =[5]WR_sum_PT_Year_AF!B16 -> 2014 | D15: =[5]WR_sum_PT_Year_AF!C16 -> 71054.8
B16: =[5]WR_sum_PT_Year_AF!A17 -> 2012 | C16: =[5]WR_sum_PT_Year_AF!B17 -> 2417 | D16: =[5]WR_sum_PT_Year_AF!C17 -> 102711.6
B17: =[5]WR_sum_PT_Year_AF!A18 -> 2013 | C17: =[5]WR_sum_PT_Year_AF!B18 -> 2163 | D17: =[5]WR_sum_PT_Year_AF!C18 -> 98532.5
B18: =[5]WR_sum_PT_Year_AF!A19 -> 2014 | C18: =[5]WR_sum_PT_Year_AF!B19 -> 2035 | D18: =[5]WR_sum_PT_Year_AF!C19 -> 108259.7
B19: =[5]WR_sum_PT_Year_AF!A20 -> 2015 | C19: =[5]WR_sum_PT_Year_AF!B20 -> 1318 | D19: =[5]WR_sum_PT_Year_AF!C20 -> 94577.1
B20: =[5]WR_sum_PT_Year_AF!A21 -> 2016 | C20: =[5]WR_sum_PT_Year_AF!B21+[5]WR_sum_PT_Year_AF!B31 -> 1227 | D20: =[5]WR_sum_PT_Year_AF!C21+[5]WR_sum_PT_Year_AF!C31 -> 94699.9
B21: =[5]WR_sum_PT_Year_AF!A22 -> 2017 | C21: =[5]WR_sum_PT_Year_AF!B22+[5]WR_sum_PT_Year_AF!B32 -> 1631 | D21: =[5]WR_sum_PT_Year_AF!C22+[5]WR_sum_PT_Year_AF!C32 -> 68870.4
B22: =[5]WR_sum_PT_Year_AF!A23 -> 2018 | C22: =[5]WR_sum_PT_Year_AF!B23 -> 1697 | D22: =[5]WR_sum_PT_Year_AF!C23 -> 76477
B23: =[5]WR_sum_PT_Year_AF!A24 -> 2019 | C23: =[5]WR_sum_PT_Year_AF!B24 -> 1217 | D23: =[5]WR_sum_PT_Year_AF!C24 -> 51207.2
B24: =[5]WR_sum_PT_Year_AF!A25 -> 2020 | C24: =[5]WR_sum_PT_Year_AF!B25 -> 428 | D24: =[5]WR_sum_PT_Year_AF!C25 -> 23558.8
B25: =[5]WR_sum_PT_Year_AF!A26 -> 2021 | C25: =[5]WR_sum_PT_Year_AF!B26 -> 435 | D25: =[5]WR_sum_PT_Year_AF!C26 -> 22465.6
B26: =[5]WR_sum_PT_Year_AF!A27 -> 2022 | C26: =[5]WR_sum_PT_Year_AF!B27 -> 601 | D26: =[5]WR_sum_PT_Year_AF!C27 -> 36145.8
B27: =[5]WR_sum_PT_Year_AF!A28 -> 2023 | C27: =[5]WR_sum_PT_Year_AF!B28 -> 539 | D27: =[5]WR_sum_PT_Year_AF!C28 -> 36120.1
B28: =[5]WR_sum_PT_Year_AF!A29 -> 2024 | C28: =[5]WR_sum_PT_Year_AF!B29 -> 513 | D28: =[5]WR_sum_PT_Year_AF!C29 -> 39591.1
B29: =[5]WR_sum_PT_Year_AF!A30 -> 2025 | C29: =[5]WR_sum_PT_Year_AF!B30 -> 341 | D29: =[5]WR_sum_PT_Year_AF!C30 -> 29678.6
B30: TOTALS | C30: =SUBTOTAL(109,C9:C29) -> 28315 | D30: =SUBTOTAL(109,D9:D29) -> 1043322.8
B38: PT Permits by Year, Use Purpose, and Amount Permitted
B40: Year | C40: Use Purpose | D40: Number of Permits | E40: Total Amount Permitted (Acre-Feet)
B41: 2000 | C41: Agriculture | D41: 4 | E41: 847.7
C42: Commercial | D42: 1 | E42: 0.3
C43: Industrial | D43: 20 | E43: 283
C44: Irrigation | D44: 29 | E44: 14595
C45: Oil, Gas & Mining | D45: 1019 | E45: 2651.9
C46: Other | D46: 0 | E46: 0
C47: Power | D47: 0 | E47: 0
C48: Public Water Supply | D48: 12 | E48: 784
C49: Recreation, Fish & Wildlife | D49: 0 | E49: 0
B50: 2001 | C50: Agriculture | D50: 4 | E50: 210
C51: Commercial | D51: 2 | E51: 5.5
C52: Industrial | D52: 22 | E52: 196.9
...

Sheet PT Graph Data
A1: Year | B1: Use Purpose | C1: Number of Permits | D1: Total Amount Permitted
A2: 1998 | B2: Oil, Gas & Mining | C2: 904 | D2: 2532.4
A3: 1999 | B3: Oil, Gas & Mining | C3: 640 | D3: 1955.5
A4: 2000 | B4: Oil, Gas & Mining | C4: 1019 | D4: 2651.9
A5: 2001 | B5: Oil, Gas & Mining | C5: 982 | D5: 2914
A6: 2002 | B6: Oil, Gas & Mining | C6: 793 | D6: 2270.4
A7: 2003 | B7: Oil, Gas & Mining | C7: 1206 | D7: 3233.4
A8: 2004 | B8: Oil, Gas & Mining | C8: 1449 | D8: 5252.8
A9: 2005 | B9: Oil, Gas & Mining | C9: 1628 | D9: 5472.4
A10: 2006 | B10: Oil, Gas & Mining | C10: 1794 | D10: 3546.5
A11: 2007 | B11: Oil, Gas & Mining | C11: ='Provisional-Temporary Permits'!D108 -> 1792 | D11: ='Provisional-Temporary Permits'!E108 -> 4228.8
A12: 2008 | B12: Oil, Gas & Mining | C12: ='Provisional-Temporary Permits'!D117 -> 1993 | D12: ='Provisional-Temporary Permits'!E117 -> 7956.5
A13: 2009 | B13: Oil, Gas & Mining | C13: ='Provisional-Temporary Permits'!D126 -> 875 | D13: ='Provisional-Temporary Permits'!E126 -> 6485.8
A14: 2010 | B14: Oil, Gas & Mining | C14: ='Provisional-Temporary Permits'!D135 -> 1286 | D14: ='Provisional-Temporary Permits'!E135 -> 9320.4
A15: 2011 | B15: Oil, Gas & Mining | C15: ='Provisional-Temporary Permits'!D144 -> 1895 | D15: ='Provisional-Temporary Permits'!E144 -> 15701.8
A16: 2012 | B16: Oil, Gas & Mining | C16: ='Provisional-Temporary Permits'!D153 -> 2270 | D16: ='Provisional-Temporary Permits'!E153 -> 23546.1
A17: 2013 | B17: Oil, Gas & Mining | C17: ='Provisional-Temporary Permits'!D162 -> 2048 | D17: ='Provisional-Temporary Permits'!E162 -> 27446.8
A18: 2014 | B18: Oil, Gas & Mining | C18: ='Provisional-Temporary Permits'!D171 -> 1925 | D18: ='Provisional-Temporary Permits'!E171 -> 30728.4
A19: 2015 | B19: Oil, Gas & Mining | C19: ='Provisional-Temporary Permits'!D180 -> 1203 | D19: ='Provisional-Temporary Permits'!E180 -> 20768.3
A20: 2016 | B20: Oil, Gas & Mining | C20: ='Provisional-Temporary Permits'!D189 -> 1161 | D20: ='Provisional-Temporary Permits'!E189 -> 24151.6
A21: 2017 | B21: Oil, Gas & Mining | C21: ='Provisional-Temporary Permits'!D198 -> 1484 | D21: ='Provisional-Temporary Permits'!E198 -> 40620.3
A22: 2018 | B22: Oil, Gas & Mining | C22: ='Provisional-Temporary Permits'!D207 -> 1552 | D22: ='Provisional-Temporary Permits'!E207 -> 49789.1
A23: 2019 | B23: Oil, Gas & Mining | C23: ='Provisional-Temporary Permits'!D216 -> 1079 | D23: ='Provisional-Temporary Permits'!E216 -> 41905.6
A24: 2020 | B24: Oil, Gas & Mining | C24: ='Provisional-Temporary Permits'!D225 -> 362 | D24: ='Provisional-Temporary Permits'!E225 -> 12209.7
A25: 2021 | B25: Oil, Gas & Mining | C25: ='Provisional-Temporary Permits'!D234 -> 369 | D25: ='Provisional-Temporary Permits'!E234 -> 12696.2
A26: 2022 | B26: Oil, Gas & Mining | C26: ='Provisional-Temporary Permits'!D243 -> 492 | D26: ='Provisional-Temporary Permits'!E243 -> 17068.6
A27: 2023 | B27: Oil, Gas & Mining | C27: ='Provisional-Temporary Permits'!D252 -> 427 | D27: ='Provisional-Temporary Permits'!E252 -> 18353
A28: 2024 | B28: Oil, Gas & Mining | C28: ='Provisional-Temporary Permits'!D261 -> 397 | D28: ='Provisional-Temporary Permits'!E261 -> 18278.7
A29: 2025 | B29: Oil, Gas & Mining | C29: ='Provisional-Temporary Permits'!D270 -> 260 | D29: ='Provisional-Temporary Permits'!E270 -> 16649.5

Sheet Sheet1
